INFO:werkzeug: * Debugger PIN: 888-243-362
INFO:werkzeug:192.168.0.101 - - [29/Aug/2025 11:25:25] "GET / HTTP/1.1" 302 -
INFO:werkzeug:192.168.0.101 - - [29/Aug/2025 11:25:25] "GET /dashboard HTTP/1.1" 200 -
INFO:werkzeug:192.168.0.101 - - [29/Aug/2025 11:25:26] "GET /static/css/style.css HTTP/1.1" 200 -
INFO:werkzeug:192.168.0.101 - - [29/Aug/2025 11:25:26] "GET /static/js/app.js HTTP/1.1" 200 -
INFO:werkzeug:192.168.0.101 - - [29/Aug/2025 11:25:26] "GET /static/js/barcode-scanner.js HTTP/1.1" 200 -
INFO:werkzeug:192.168.0.101 - - [29/Aug/2025 11:25:27] "GET /invoice_creation/ HTTP/1.1" 200 -
INFO:werkzeug:192.168.0.101 - - [29/Aug/2025 11:25:27] "GET /static/css/style.css HTTP/1.1" 304 -
INFO:werkzeug:192.168.0.101 - - [29/Aug/2025 11:25:27] "GET /static/js/app.js HTTP/1.1" 304 -
INFO:werkzeug:192.168.0.101 - - [29/Aug/2025 11:25:27] "GET /static/js/barcode-scanner.js HTTP/1.1" 304 -
INFO:werkzeug:192.168.0.101 - - [29/Aug/2025 11:25:29] "GET /invoice_creation/detail/1 HTTP/1.1" 500 -
Traceback (most recent call last):
  File "C:\Users\LENOVO\AppData\Local\Programs\Python\Python311\Lib\site-packages\sqlalchemy\engine\base.py", line 1969, in _exec_single_context
    self.dialect.do_execute(
  File "C:\Users\LENOVO\AppData\Local\Programs\Python\Python311\Lib\site-packages\sqlalchemy\engine\default.py", line 922, in do_execute
    cursor.execute(statement, parameters)
  File "C:\Users\LENOVO\AppData\Local\Programs\Python\Python311\Lib\site-packages\pymysql\cursors.py", line 153, in execute
    result = self._query(query)
             ^^^^^^^^^^^^^^^^^^
  File "C:\Users\LENOVO\AppData\Local\Programs\Python\Python311\Lib\site-packages\pymysql\cursors.py", line 322, in _query
    conn.query(q)
  File "C:\Users\LENOVO\AppData\Local\Programs\Python\Python311\Lib\site-packages\pymysql\connections.py", line 563, in query
    self._affected_rows = self._read_query_result(unbuffered=unbuffered)
                          ^^^^^^^^^^^^^^^^^^^^^^^^^^^^^^^^^^^^^^^^^^^^^^
  File "C:\Users\LENOVO\AppData\Local\Programs\Python\Python311\Lib\site-packages\pymysql\connections.py", line 825, in _read_query_result
    result.read()
  File "C:\Users\LENOVO\AppData\Local\Programs\Python\Python311\Lib\site-packages\pymysql\connections.py", line 1199, in read
    first_packet = self.connection._read_packet()
                   ^^^^^^^^^^^^^^^^^^^^^^^^^^^^^^
  File "C:\Users\LENOVO\AppData\Local\Programs\Python\Python311\Lib\site-packages\pymysql\connections.py", line 775, in _read_packet
    packet.raise_for_error()
  File "C:\Users\LENOVO\AppData\Local\Programs\Python\Python311\Lib\site-packages\pymysql\protocol.py", line 219, in raise_for_error
    err.raise_mysql_exception(self._data)
  File "C:\Users\LENOVO\AppData\Local\Programs\Python\Python311\Lib\site-packages\pymysql\err.py", line 150, in raise_mysql_exception
    raise errorclass(errno, errval)
pymysql.err.OperationalError: (1054, "Unknown column 'invoice_lines.warehouse_name' in 'field list'")

The above exception was the direct cause of the following exception:

Traceback (most recent call last):
  File "C:\Users\LENOVO\AppData\Local\Programs\Python\Python311\Lib\site-packages\flask\app.py", line 1478, in __call__
    return self.wsgi_app(environ, start_response)
           ^^^^^^^^^^^^^^^^^^^^^^^^^^^^^^^^^^^^^^
  File "C:\Users\LENOVO\AppData\Local\Programs\Python\Python311\Lib\site-packages\werkzeug\middleware\proxy_fix.py", line 182, in __call__
    return self.app(environ, start_response)
           ^^^^^^^^^^^^^^^^^^^^^^^^^^^^^^^^^
  File "C:\Users\LENOVO\AppData\Local\Programs\Python\Python311\Lib\site-packages\flask\app.py", line 1458, in wsgi_app
    response = self.handle_exception(e)
               ^^^^^^^^^^^^^^^^^^^^^^^^
  File "C:\Users\LENOVO\AppData\Local\Programs\Python\Python311\Lib\site-packages\flask\app.py", line 1455, in wsgi_app
    response = self.full_dispatch_request()
               ^^^^^^^^^^^^^^^^^^^^^^^^^^^^
  File "C:\Users\LENOVO\AppData\Local\Programs\Python\Python311\Lib\site-packages\flask\app.py", line 869, in full_dispatch_request
    rv = self.handle_user_exception(e)
         ^^^^^^^^^^^^^^^^^^^^^^^^^^^^^
  File "C:\Users\LENOVO\AppData\Local\Programs\Python\Python311\Lib\site-packages\flask\app.py", line 867, in full_dispatch_request
    rv = self.dispatch_request()
         ^^^^^^^^^^^^^^^^^^^^^^^
  File "C:\Users\LENOVO\AppData\Local\Programs\Python\Python311\Lib\site-packages\flask\app.py", line 852, in dispatch_request
    return self.ensure_sync(self.view_functions[rule.endpoint])(**view_args)
           ^^^^^^^^^^^^^^^^^^^^^^^^^^^^^^^^^^^^^^^^^^^^^^^^^^^^^^^^^^^^^^^^^
  File "C:\Users\LENOVO\AppData\Local\Programs\Python\Python311\Lib\site-packages\flask_login\utils.py", line 290, in decorated_view
    return current_app.ensure_sync(func)(*args, **kwargs)
           ^^^^^^^^^^^^^^^^^^^^^^^^^^^^^^^^^^^^^^^^^^^^^^
  File "E:\SAP_Integ\Git Change\20250829\5\IT_Web_Odd_On\modules\invoice_creation\routes.py", line 106, in detail
    return render_template('invoice_creation/detail.html', invoice=invoice)
           ^^^^^^^^^^^^^^^^^^^^^^^^^^^^^^^^^^^^^^^^^^^^^^^^^^^^^^^^^^^^^^^^
  File "C:\Users\LENOVO\AppData\Local\Programs\Python\Python311\Lib\site-packages\flask\templating.py", line 152, in render_template
    return _render(app, template, context)
           ^^^^^^^^^^^^^^^^^^^^^^^^^^^^^^^
  File "C:\Users\LENOVO\AppData\Local\Programs\Python\Python311\Lib\site-packages\flask\templating.py", line 133, in _render
    rv = template.render(context)
         ^^^^^^^^^^^^^^^^^^^^^^^^
  File "C:\Users\LENOVO\AppData\Local\Programs\Python\Python311\Lib\site-packages\jinja2\environment.py", line 1301, in render
    self.environment.handle_exception()
  File "C:\Users\LENOVO\AppData\Local\Programs\Python\Python311\Lib\site-packages\jinja2\environment.py", line 936, in handle_exception
    raise rewrite_traceback_stack(source=source)
  File "E:\SAP_Integ\Git Change\20250829\5\IT_Web_Odd_On\templates\invoice_creation\detail.html", line 1, in top-level template code
    {% extends "base.html" %}
  File "E:\SAP_Integ\Git Change\20250829\5\IT_Web_Odd_On\templates\base.html", line 185, in top-level template code
    {% block content %}{% endblock %}
  File "E:\SAP_Integ\Git Change\20250829\5\IT_Web_Odd_On\templates\invoice_creation\detail.html", line 96, in block 'content'
    {% if invoice.lines %}
  File "C:\Users\LENOVO\AppData\Local\Programs\Python\Python311\Lib\site-packages\jinja2\environment.py", line 485, in getattr
    return getattr(obj, attribute)
           ^^^^^^^^^^^^^^^^^^^^^^^
  File "C:\Users\LENOVO\AppData\Local\Programs\Python\Python311\Lib\site-packages\sqlalchemy\orm\attributes.py", line 566, in __get__
    return self.impl.get(state, dict_)  # type: ignore[no-any-return]
           ^^^^^^^^^^^^^^^^^^^^^^^^^^^^^^^^^^^^^^^^^^^^^^^^^^^^^^^^^^
  File "C:\Users\LENOVO\AppData\Local\Programs\Python\Python311\Lib\site-packages\sqlalchemy\orm\attributes.py", line 1086, in get
    value = self._fire_loader_callables(state, key, passive)
            ^^^^^^^^^^^^^^^^^^^^^^^^^^^^^^^^^^^^^^^^^^^^^^^^
  File "C:\Users\LENOVO\AppData\Local\Programs\Python\Python311\Lib\site-packages\sqlalchemy\orm\attributes.py", line 1121, in _fire_loader_callables
    return self.callable_(state, passive)
           ^^^^^^^^^^^^^^^^^^^^^^^^^^^^^^
  File "C:\Users\LENOVO\AppData\Local\Programs\Python\Python311\Lib\site-packages\sqlalchemy\orm\strategies.py", line 967, in _load_for_state
    return self._emit_lazyload(
           ^^^^^^^^^^^^^^^^^^^^
  File "C:\Users\LENOVO\AppData\Local\Programs\Python\Python311\Lib\site-packages\sqlalchemy\orm\strategies.py", line 1130, in _emit_lazyload
    result = session.execute(
             ^^^^^^^^^^^^^^^^
  File "C:\Users\LENOVO\AppData\Local\Programs\Python\Python311\Lib\site-packages\sqlalchemy\orm\session.py", line 2308, in execute
    return self._execute_internal(
           ^^^^^^^^^^^^^^^^^^^^^^^
  File "C:\Users\LENOVO\AppData\Local\Programs\Python\Python311\Lib\site-packages\sqlalchemy\orm\session.py", line 2190, in _execute_internal
    result: Result[Any] = compile_state_cls.orm_execute_statement(
                          ^^^^^^^^^^^^^^^^^^^^^^^^^^^^^^^^^^^^^^^^
  File "C:\Users\LENOVO\AppData\Local\Programs\Python\Python311\Lib\site-packages\sqlalchemy\orm\context.py", line 293, in orm_execute_statement
    result = conn.execute(
             ^^^^^^^^^^^^^
  File "C:\Users\LENOVO\AppData\Local\Programs\Python\Python311\Lib\site-packages\sqlalchemy\engine\base.py", line 1416, in execute
    return meth(
           ^^^^^
  File "C:\Users\LENOVO\AppData\Local\Programs\Python\Python311\Lib\site-packages\sqlalchemy\sql\elements.py", line 516, in _execute_on_connection
    return connection._execute_clauseelement(
           ^^^^^^^^^^^^^^^^^^^^^^^^^^^^^^^^^^
  File "C:\Users\LENOVO\AppData\Local\Programs\Python\Python311\Lib\site-packages\sqlalchemy\engine\base.py", line 1639, in _execute_clauseelement
    ret = self._execute_context(
          ^^^^^^^^^^^^^^^^^^^^^^
  File "C:\Users\LENOVO\AppData\Local\Programs\Python\Python311\Lib\site-packages\sqlalchemy\engine\base.py", line 1848, in _execute_context
    return self._exec_single_context(
           ^^^^^^^^^^^^^^^^^^^^^^^^^^
  File "C:\Users\LENOVO\AppData\Local\Programs\Python\Python311\Lib\site-packages\sqlalchemy\engine\base.py", line 1988, in _exec_single_context
    self._handle_dbapi_exception(
  File "C:\Users\LENOVO\AppData\Local\Programs\Python\Python311\Lib\site-packages\sqlalchemy\engine\base.py", line 2343, in _handle_dbapi_exception
    raise sqlalchemy_exception.with_traceback(exc_info[2]) from e
  File "C:\Users\LENOVO\AppData\Local\Programs\Python\Python311\Lib\site-packages\sqlalchemy\engine\base.py", line 1969, in _exec_single_context
    self.dialect.do_execute(
  File "C:\Users\LENOVO\AppData\Local\Programs\Python\Python311\Lib\site-packages\sqlalchemy\engine\default.py", line 922, in do_execute
    cursor.execute(statement, parameters)
  File "C:\Users\LENOVO\AppData\Local\Programs\Python\Python311\Lib\site-packages\pymysql\cursors.py", line 153, in execute
    result = self._query(query)
             ^^^^^^^^^^^^^^^^^^
  File "C:\Users\LENOVO\AppData\Local\Programs\Python\Python311\Lib\site-packages\pymysql\cursors.py", line 322, in _query
    conn.query(q)
  File "C:\Users\LENOVO\AppData\Local\Programs\Python\Python311\Lib\site-packages\pymysql\connections.py", line 563, in query
    self._affected_rows = self._read_query_result(unbuffered=unbuffered)
                          ^^^^^^^^^^^^^^^^^^^^^^^^^^^^^^^^^^^^^^^^^^^^^^
  File "C:\Users\LENOVO\AppData\Local\Programs\Python\Python311\Lib\site-packages\pymysql\connections.py", line 825, in _read_query_result
    result.read()
  File "C:\Users\LENOVO\AppData\Local\Programs\Python\Python311\Lib\site-packages\pymysql\connections.py", line 1199, in read
    first_packet = self.connection._read_packet()
                   ^^^^^^^^^^^^^^^^^^^^^^^^^^^^^^
  File "C:\Users\LENOVO\AppData\Local\Programs\Python\Python311\Lib\site-packages\pymysql\connections.py", line 775, in _read_packet
    packet.raise_for_error()
  File "C:\Users\LENOVO\AppData\Local\Programs\Python\Python311\Lib\site-packages\pymysql\protocol.py", line 219, in raise_for_error
    err.raise_mysql_exception(self._data)
  File "C:\Users\LENOVO\AppData\Local\Programs\Python\Python311\Lib\site-packages\pymysql\err.py", line 150, in raise_mysql_exception
    raise errorclass(errno, errval)
sqlalchemy.exc.OperationalError: (pymysql.err.OperationalError) (1054, "Unknown column 'invoice_lines.warehouse_name' in 'field list'")
[SQL: SELECT invoice_lines.id AS invoice_lines_id, invoice_lines.invoice_id AS invoice_lines_invoice_id, invoice_lines.line_number AS invoice_lines_line_number, invoice_lines.item_
code AS invoice_lines_item_code, invoice_lines.item_description AS invoice_lines_item_description, invoice_lines.quantity AS invoice_lines_quantity, invoice_lines.unit_price AS inv
oice_lines_unit_price, invoice_lines.line_total AS invoice_lines_line_total, invoice_lines.warehouse_code AS invoice_lines_warehouse_code, invoice_lines.warehouse_name AS invoice_lines_warehouse_name, invoice_lines.tax_code AS invoice_lines_tax_code, invoice_lines.created_at AS invoice_lines_created_at, invoice_lines.updated_at AS invoice_lines_updated_at   
FROM invoice_lines
WHERE %(param_1)s = invoice_lines.invoice_id]
[parameters: {'param_1': 1}]
(Background on this error at: https://sqlalche.me/e/20/e3q8)
INFO:werkzeug:192.168.0.101 - - [29/Aug/2025 11:25:30] "GET /invoice_creation/detail/1?__debugger__=yes&cmd=resource&f=style.css HTTP/1.1" 200 -
INFO:werkzeug:192.168.0.101 - - [29/Aug/2025 11:25:30] "GET /invoice_creation/detail/1?__debugger__=yes&cmd=resource&f=debugger.js HTTP/1.1" 200 -
INFO:werkzeug:192.168.0.101 - - [29/Aug/2025 11:25:30] "GET /invoice_creation/detail/1?__debugger__=yes&cmd=resource&f=console.png HTTP/1.1" 200 -
INFO:werkzeug:192.168.0.101 - - [29/Aug/2025 11:25:30] "GET /invoice_creation/detail/1?__debugger__=yes&cmd=resource&f=console.png HTTP/1.1" 304 -
INFO:werkzeug:192.168.0.101 - - [29/Aug/2025 11:25:34] "GET /invoice_creation/create HTTP/1.1" 200 -
INFO:werkzeug:192.168.0.101 - - [29/Aug/2025 11:25:34] "GET /static/css/style.css HTTP/1.1" 304 -
INFO:werkzeug:192.168.0.101 - - [29/Aug/2025 11:25:34] "GET /static/js/app.js HTTP/1.1" 304 -
INFO:werkzeug:192.168.0.101 - - [29/Aug/2025 11:25:34] "GET /static/js/barcode-scanner.js HTTP/1.1" 304 -
INFO:werkzeug:192.168.0.101 - - [29/Aug/2025 11:25:34] "POST /invoice_creation/create_draft HTTP/1.1" 200 -
INFO:werkzeug:192.168.0.101 - - [29/Aug/2025 11:25:35] "GET /invoice_creation/api/business-partners HTTP/1.1" 200 -
transfer_item (repr) --> {'odata.metadata': 'https://192.168.0.101:50000/b1s/v1/$metadata#SAPB1.SQLQueryResult', 'SqlText': "SELECT T0.[ItemCode],T0.[itemName], T0.[DistNumber], T2
.[WhsCode],T2.[WhsName],T3.[BPLName],T2.[BPLid] FROM [OSRN] T0 INNER JOIN [OSRQ] T1 ON T0.[AbsEntry] =T1.[MdAbsEntry] INNER JOIN [OWHS] T2 ON T2.[WhsCode]=T1.[WhsCode] INNER JOIN [
OBPL] T3 ON T3.[BPLId]=T2.[BPLid]WHERE  T1.[Quantity] >'0'AND T0.[DistNumber]=:serial_number", 'value': [{'BPLName': 'ORD-CHENNAI', 'BPLid': 5, 'DistNumber': 'IP248', 'ItemCode': 'IPhone', 'WhsCode': '7000-FG', 'WhsName': 'Finished Goods GST-ORD DC CHN - Assigned to AVS', 'itemName': '12 Series 8GB RAM/250 GB ROM Black'}]}
INFO:werkzeug:192.168.0.101 - - [29/Aug/2025 11:25:42] "GET /invoice_creation/api/validate-serial-number?serial_number=IP248 HTTP/1.1" 200 -
ERROR:root:❌ Error adding serial item: (pymysql.err.OperationalError) (1054, "Unknown column 'warehouse_name' in 'field list'")
[SQL: INSERT INTO invoice_lines (invoice_id, line_number, item_code, item_description, quantity, unit_price, line_total, warehouse_code, warehouse_name, tax_code, created_at, updat
ed_at) VALUES (%(invoice_id)s, %(line_number)s, %(item_code)s, %(item_description)s, %(quantity)s, %(unit_price)s, %(line_total)s, %(warehouse_code)s, %(warehouse_name)s, %(tax_code)s, %(created_at)s, %(updated_at)s)]
[parameters: {'invoice_id': 2, 'line_number': 1, 'item_code': 'IPhone', 'item_description': '12 Series 8GB RAM/250 GB ROM Black', 'quantity': 1.0, 'unit_price': None, 'line_total':
 None, 'warehouse_code': '7000-FG', 'warehouse_name': 'Finished Goods GST-ORD DC CHN - Assigned to AVS', 'tax_code': 'CSGST@18', 'created_at': datetime.datetime(2025, 8, 29, 5, 55, 43, 854792), 'updated_at': datetime.datetime(2025, 8, 29, 5, 55, 43, 854792)}]
(Background on this error at: https://sqlalche.me/e/20/e3q8)
INFO:werkzeug:192.168.0.101 - - [29/Aug/2025 11:25:43] "POST /invoice_creation/2/add_line_item HTTP/1.1" 500 -
